Workbook

Sheet Recruitment_Data
A1: Candidate_ID | B1: Recruiter | C1: Job_Title | D1: Department | E1: Application_Date | F1: Interview_Date | G1: Offer_Date | H1: Hire_Date | I1: Source | J1: Status | K1: Salary | L1: Days_to_Hire
A2: C001 | B2: Alex | C2: Data Analyst | D2: Analytics | E2: 46027 | F2: 46032 | G2: 46037 | H2: 46044 | I2: LinkedIn | J2: Hired | K2: 72000 | L2: =IF(H2="","",H2-E2) -> 17
A3: C002 | B3: Sarah | C3: Business Analyst | D3: Analytics | E3: 46029 | F3: 46036 | G3: 46042 | H3: 46049 | I3: Indeed | J3: Hired | K3: 76000 | L3: =IF(H3="","",H3-E3) -> 20
A4: C003 | B4: David | C4: SQL Developer | D4: IT | E4: 46030 | F4: 46038 | I4: LinkedIn | J4: Rejected | L4: =IF(H4="","",H4-E4)
A5: C004 | B5: Alex | C5: Financial Analyst | D5: Finance | E5: 46034 | F5: 46040 | G5: 46045 | H5: 46052 | I5: Referral | J5: Hired | K5: 70000 | L5: =IF(H5="","",H5-E5) -> 18
A6: C005 | B6: Maria | C6: Data Analyst | D6: Analytics | E6: 46037 | F6: 46043 | I6: Indeed | J6: Rejected | L6: =IF(H6="","",H6-E6)
A7: C006 | B7: Sarah | C7: HR Analyst | D7: Human Resources | E7: 46040 | F7: 46047 | G7: 46052 | H7: 46059 | I7: Referral | J7: Hired | K7: 65000 | L7: =IF(H7="","",H7-E7) -> 19
A8: C007 | B8: David | C8: BI Analyst | D8: Analytics | E8: 46042 | F8: 46049 | G8: 46055 | H8: 46062 | I8: LinkedIn | J8: Hired | K8: 80000 | L8: =IF(H8="","",H8-E8) -> 20
A9: C008 | B9: Maria | C9: SQL Developer | D9: IT | E9: 46044 | F9: 46051 | I9: Company Website | J9: Rejected | L9: =IF(H9="","",H9-E9)
A10: C009 | B10: Alex | C10: Business Analyst | D10: Operations | E10: 46047 | F10: 46055 | G10: 46059 | H10: 46066 | I10: Indeed | J10: Hired | K10: 74000 | L10: =IF(H10="","",H10-E10) -> 19
A11: C010 | B11: Sarah | C11: Data Analyst | D11: Analytics | E11: 46050 | F11: 46057 | I11: Referral | J11: Rejected | L11: =IF(H11="","",H11-E11)
A12: C011 | B12: Alex | C12: Data Analyst | D12: Analytics | E12: 46217 | F12: 46222 | G12: 46226 | H12: 46236 | I12: Referral | J12: Hired | K12: 82000 | L12: =IF(H12="","",H12-E12) -> 19
A13: C012 | B13: Maria | C13: Data Analyst | D13: Analytics | E13: 46076 | F13: 46081 | G13: 46089 | H13: 46098 | I13: LinkedIn | J13: Hired | K13: 65000 | L13: =IF(H13="","",H13-E13) -> 22
A14: C013 | B14: Sarah | C14: HR Analyst | D14: Human Resources | E14: 46197 | F14: 46205 | G14: 46211 | H14: 46216 | I14: Company Website | J14: Hired | K14: 63000 | L14: =IF(H14="","",H14-E14) -> 19
A15: C014 | B15: Maria | C15: BI Analyst | D15: Analytics | E15: 46232 | F15: 46242 | G15: 46248 | H15: 46253 | I15: Referral | J15: Hired | K15: 77000 | L15: =IF(H15="","",H15-E15) -> 21
A16: C015 | B16: Alex | C16: BI Analyst | D16: Analytics | E16: 46151 | F16: 46161 | I16: Referral | J16: Rejected | L16: =IF(H16="","",H16-E16)
A17: C016 | B17: Maria | C17: Financial Analyst | D17: Finance | E17: 46065 | F17: 46072 | I17: LinkedIn | J17: Rejected | L17: =IF(H17="","",H17-E17)
A18: C017 | B18: David | C18: Operations Analyst | D18: Operations | E18: 46074 | F18: 46083 | I18: Referral | J18: Rejected | L18: =IF(H18="","",H18-E18)
A19: C018 | B19: Alex | C19: HR Analyst | D19: Human Resources | E19: 46071 | F19: 46075 | I19: Indeed | J19: Rejected | L19: =IF(H19="","",H19-E19)
A20: C019 | B20: Alex | C20: SQL Developer | D20: IT | E20: 46113 | F20: 46123 | G20: 46129 | H20: 46135 | I20: Referral | J20: Hired | K20: 89000 | L20: =IF(H20="","",H20-E20) -> 22
A21: C020 | B21: Sarah | C21: HR Analyst | D21: Human Resources | E21: 46144 | F21: 46153 | I21: Referral | J21: Rejected | L21: =IF(H21="","",H21-E21)
A22: C021 | B22: Alex | C22: Financial Analyst | D22: Finance | E22: 46219 | F22: 46224 | G22: 46229 | H22: 46237 | I22: Indeed | J22: Hired | K22: 77000 | L22: =IF(H22="","",H22-E22) -> 18
A23: C022 | B23: Sarah | C23: HR Analyst | D23: Human Resources | E23: 46123 | F23: 46133 | I23: Referral | J23: Rejected | L23: =IF(H23="","",H23-E23)
A24: C023 | B24: Sarah | C24: Operations Analyst | D24: Operations | E24: 46068 | F24: 46075 | I24: LinkedIn | J24: Rejected | L24: =IF(H24="","",H24-E24)
A25: C024 | B25: Alex | C25: Business Analyst | D25: Analytics | E25: 46122 | F25: 46129 | G25: 46136 | H25: 46146 | I25: Referral | J25: Hired | K25: 82000 | L25: =IF(H25="","",H25-E25) -> 24
A26: C025 | B26: David | C26: Business Analyst | D26: Analytics | E26: 46090 | F26: 46098 | I26: Indeed | J26: Rejected | L26: =IF(H26="","",H26-E26)
A27: C026 | B27: Maria | C27: Financial Analyst | D27: Finance | E27: 46121 | F27: 46126 | G27: 46134 | H27: 46142 | I27: Company Website | J27: Hired | K27: 67000 | L27: =IF(H27="","",H27-E27) -> 21
A28: C027 | B28: Alex | C28: Business Analyst | D28: Analytics | E28: 46066 | F28: 46073 | I28: Indeed | J28: Rejected | L28: =IF(H28="","",H28-E28)
A29: C028 | B29: Alex | C29: SQL Developer | D29: IT | E29: 46206 | F29: 46213 | I29: Company Website | J29: Rejected | L29: =IF(H29="","",H29-E29)
A30: C029 | B30: David | C30: Financial Analyst | D30: Finance | E30: 46189 | F30: 46193 | I30: LinkedIn | J30: Rejected | L30: =IF(H30="","",H30-E30)
A31: C030 | B31: David | C31: Operations Analyst | D31: Operations | E31: 46228 | F31: 46235 | G31: 46240 | H31: 46248 | I31: Referral | J31: Hired | K31: 62000 | L31: =IF(H31="","",H31-E31) -> 20
A32: C031 | B32: Sarah | C32: Financial Analyst | D32: Finance | E32: 46121 | F32: 46127 | I32: LinkedIn | J32: Rejected | L32: =IF(H32="","",H32-E32)
A33: C032 | B33: Sarah | C33: Business Analyst | D33: Analytics | E33: 46217 | F33: 46225 | I33: Referral | J33: Rejected | L33: =IF(H33="","",H33-E33)
A34: C033 | B34: Alex | C34: Financial Analyst | D34: Finance | E34: 46189 | F34: 46193 | G34: 46199 | H34: 46206 | I34: Referral | J34: Hired | K34: 72000 | L34: =IF(H34="","",H34-E34) -> 17
A35: C034 | B35: Sarah | C35: Financial Analyst | D35: Finance | E35: 46068 | F35: 46075 | G35: 46079 | H35: 46088 | I35: LinkedIn | J35: Hired | K35: 69000 | L35: =IF(H35="","",H35-E35) -> 20
A36: C035 | B36: Maria | C36: Financial Analyst | D36: Finance | E36: 46086 | F36: 46096 | G36: 46104 | H36: 46112 | I36: Indeed | J36: Hired | K36: 71000 | L36: =IF(H36="","",H36-E36) -> 26
A37: C036 | B37: Sarah | C37: HR Analyst | D37: Human Resources | E37: 46192 | F37: 46201 | G37: 46207 | H37: 46215 | I37: Referral | J37: Hired | K37: 74000 | L37: =IF(H37="","",H37-E37) -> 23
A38: C037 | B38: Alex | C38: Business Analyst | D38: Analytics | E38: 46169 | F38: 46173 | G38: 46181 | H38: 46190 | I38: Indeed | J38: Hired | K38: 75000 | L38: =IF(H38="","",H38-E38) -> 21
A39: C038 | B39: Sarah | C39: Data Analyst | D39: Analytics | E39: 46204 | F39: 46208 | I39: LinkedIn | J39: Rejected | L39: =IF(H39="","",H39-E39)
A40: C039 | B40: Alex | C40: Data Analyst | D40: Analytics | E40: 46112 | F40: 46117 | G40: 46123 | H40: 46133 | I40: Referral | J40: Hired | K40: 80000 | L40: =IF(H40="","",H40-E40) -> 21
...

Sheet Recruiter_Analysis
A3: Count of Candidate_ID | B3: Column Labels
A4: Row Labels | B4: Hired | C4: Rejected | D4: Grand Total
A5: Alex | B5: 27 | C5: 15 | D5: 42
A6: David | B6: 22 | C6: 15 | D6: 37
A7: Maria | B7: 16 | C7: 18 | D7: 34
A8: Sarah | B8: 20 | C8: 17 | D8: 37
A9: Grand Total | B9: 85 | C9: 65 | D9: 150
A20: Recruiter | B20: Hired | C20: Total Candidates | D20: Hiring Rate
A21: Alex | B21: =GETPIVOTDATA("Candidate_ID",$A$3,"Recruiter","Alex","Status ","Hired") -> 27 | C21: =GETPIVOTDATA("Candidate_ID",$A$3,"Recruiter","Alex") -> 42 | D21: =B21/C21 -> 0.64285714
A22: David | B22: =GETPIVOTDATA("Candidate_ID",$A$3,"Recruiter","David","Status ","Hired") -> 22 | C22: =GETPIVOTDATA("Candidate_ID",$A$3,"Recruiter","David") -> 37 | D22: =B22/C22 -> 0.59459459
A23: Maria | B23: =GETPIVOTDATA("Candidate_ID",$A$3,"Recruiter","Maria","Status ","Hired") -> 16 | C23: =GETPIVOTDATA("Candidate_ID",$A$3,"Recruiter","Maria") -> 34 | D23: =B23/C23 -> 0.47058824
A24: Sarah | B24: =GETPIVOTDATA("Candidate_ID",$A$3,"Recruiter","Sarah","Status ","Hired") -> 20 | C24: =GETPIVOTDATA("Candidate_ID",$A$3,"Recruiter","Sarah") -> 37 | D24: =B24/C24 -> 0.54054054
A35: Source | B35: Hired | C35: Total Candidates | D35: Hiring Rate
A36: Company Website | B36: =GETPIVOTDATA("Candidate_ID",Sheet5!$A$3,"Source","Company Website","Status ","Hired") -> 23 | C36: =GETPIVOTDATA("Candidate_ID",Sheet5!$A$3,"Source","Company Website") -> 39 | D36: =B36/C36 -> 0.58974359
A37: Indeed | B37: =GETPIVOTDATA("Candidate_ID",Sheet5!$A$3,"Source","Indeed","Status ","Hired") -> 16 | C37: =GETPIVOTDATA("Candidate_ID",Sheet5!$A$3,"Source","Indeed") -> 33 | D37: =B37/C37 -> 0.48484848
A38: LinkedIn | B38: =GETPIVOTDATA("Candidate_ID",Sheet5!$A$3,"Source","LinkedIn","Status ","Hired") -> 21 | C38: =GETPIVOTDATA("Candidate_ID",Sheet5!$A$3,"Source","LinkedIn") -> 39 | D38: =B38/C38 -> 0.53846154
A39: Referral | B39: =GETPIVOTDATA("Candidate_ID",Sheet5!$A$3,"Source","Referral","Status ","Hired") -> 25 | C39: =GETPIVOTDATA("Candidate_ID",Sheet5!$A$3,"Source","Referral") -> 39 | D39: =B39/C39 -> 0.64102564

Sheet Recruitment Dashboard
B2: Recruitment Analytics Dashboard
B5: Total Candidates | C5: 150
B6: Total Hired | C6: 85
B7: Total Rejected | C7: 65
B8: Overall Hiring Rate | C8: 0.5667
B9: Average Days to Hire | C9: 20.98

Sheet Insights
A1: Recruitment Analytics - Key Insights
A3: 1. Overall Hiring Performance
A4: Out of 150 candidates, 85 were hired and 65 were rejected, resulting in an overall hiring rate of 56.67%.
A6: 2. Recruiter Performance
A7: Alex had the highest hiring rate at 64.29%, while Maria had the lowest at 47.06%. David and Sarah recorded hiring rates of 59.46% and 54.05%, respectively.
A9: 3. Recruitment Source Effectiveness
A10: Referral had the highest hiring rate at 64.10%, while indeed had the lowest at 48.48%. Company Website and LinkedIn had hiring rates of 58.97% and 53.85%, respectively.
A12: 4.Hiring Volume by Recruitment Source
A13: Referral generated the highest number of hires with 25, followed by Company Website with 23, LinkedIn with 21, and Indeed with 16 hires.
A15: 5. Recruiter Hiring Volume
A16: Alex recorded the highest number of hires with 27, followed by David with 22, Sarah with 20, and Maria with 16 hires.
A18: Business Recommendations
... A22: 3. Review the recruiting practices used by higher performimg recruiters, particularly Alex, to identify approaches that could be shared across the recruitment team.

Sheet Sheet3
A1: Status | B1: Hired
A3: Row Labels | B3: Count of Candidate_ID
A4: Company Website | B4: 23
A5: Indeed | B5: 16
A6: LinkedIn | B6: 21
A7: Referral | B7: 25
A8: Grand Total | B8: 85

Sheet Sheet4
A1: Status | B1: Hired
A3: Row Labels | B3: Average of Days_to_Hire
A4: Company Website | B4: 21.608696
A5: Indeed | B5: 20.5625
A6: LinkedIn | B6: 20.428571
A7: Referral | B7: 21.12
A8: Grand Total | B8: 20.976471

Sheet Sheet5
A3: Count of Candidate_ID | B3: Column Labels
A4: Row Labels | B4: Hired | C4: Rejected | D4: Grand Total
A5: Company Website | B5: 23 | C5: 16 | D5: 39
A6: Indeed | B6: 16 | C6: 17 | D6: 33
A7: LinkedIn | B7: 21 | C7: 18 | D7: 39
A8: Referral | B8: 25 | C8: 14 | D8: 39
A9: Grand Total | B9: 85 | C9: 65 | D9: 150
